<?xml version="1.0" ?>
<!-- =================================================================================== -->
<!-- |    This document was autogenerated by xacro from pioneer-lx-jaco2.urdf.xacro    | -->
<!-- |    EDITING THIS FILE BY HAND IS NOT RECOMMENDED                                 | -->
<!-- =================================================================================== -->
<robot name="pioneer-lx-jaco2" xmlns:body="http://playerstage.sourceforge.net/gazebo/xmlschema/#body" xmlns:controller="http://playerstage.sourceforge.net/gazebo/xmlschema/#controller" xmlns:gazebo="http://playerstage.sourceforge.net/gazebo/xmlschema/#gz" xmlns:geom="http://playerstage.sourceforge.net/gazebo/xmlschema/#geom" xmlns:interface="http://playerstage.sourceforge.net/gazebo/xmlschema/#interface" xmlns:joint="http://playerstage.sourceforge.net/gazebo/xmlschema/#joint" xmlns:model="http://playerstage.sourceforge.net/gazebo/xmlschema/#model" xmlns:physics="http://playerstage.sourceforge.net/gazebo/xmlschema/#physics" xmlns:renderable="http://playerstage.sourceforge.net/gazebo/xmlschema/#renderable" xmlns:rendering="http://playerstage.sourceforge.net/gazebo/xmlschema/#rendering" xmlns:sensor="http://playerstage.sourceforge.net/gazebo/xmlschema/#sensor" xmlns:xacro="http://www.ros.org/wiki/xacro" xmlns:xi="http://www.w3.org/2001/XInclude">
  <!-- TODO share pioneer lx mobile robot components with pioneer-lx urdf by
including macro. -->
  <link name="base_link">
    <!-- base_link origin point is center of rotation, on the floor. -->
    <visual name="base_link_visual">
      <geometry name="base_link_visual_geom">
        <mesh filename="package://amr_robots_description/meshes/pioneer-lx/pioneer-lx_visual.stl" scale="0.001 0.001 0.001"/>
        <!-- box size="0.697 0.5 0.333" / -->
      </geometry>
      <origin rpy="0 0 1.570796" xyz="0 0 0"/>
      <material name="lx_red_mat">
        <color rgba="0.8 0.1 0.1 1.0"/>
      </material>
    </visual>
    <collision name="base_link_collision">
      <geometry name="base_link_collision_geom">
        <box size="0.697 0.5 0.35"/>
        <!-- box size="0.697 0.5 0.35" / -->
      </geometry>
      <origin rpy="0 0 0" xyz="0 0 0.200"/>
    </collision>
  </link>
  <!-- for some reason KDL wants this to be a separate link -->
  <link name="robot_mass">
    <inertial>
      <mass value="57.8"/>
      <!-- 60 kg minus each wheel -->
      <inertia ixx="1" ixy="0" ixz="0" iyy="1" iyz="0" izz="1"/>
    </inertial>
  </link>
  <joint name="robot_mass_attach" type="fixed">
    <parent link="base_link"/>
    <child link="robot_mass"/>
  </joint>
  <!-- right wheel -->
  <link name="r_wheel">
    <inertial>
      <mass value="1.1"/>
      <!-- kg -->
      <inertia ixx="0.02" ixy="0" ixz="0" iyy="0.02" iyz="0" izz="0.01"/>
    </inertial>
    <!--
TODO separate out pioner lx wheels in visual model 
    <visual name="r_wheel_dumb_visual">
      <geometry name="r_wheel_dumb_visual_geom">
        <cylinder radius="0.100" length="0.05" />
      </geometry>
      <origin rpy="1.570796 0 0" />
      <material name="lx_grey_mat">
        <color rgba="0.8 0.8 0.8 1.0" />
      </material>
    </visual>
-->
    <collision name="r_wheel_collision">
      <geometry name="r_wheel_collision_geom">
        <cylinder length="0.05" radius="0.100"/>
      </geometry>
      <origin rpy="1.570796 0 0"/>
    </collision>
  </link>
  <!-- left wheel -->
  <link name="l_wheel">
    <inertial>
      <mass value="1.1"/>
      <!-- kg -->
      <inertia ixx="0.02" ixy="0" ixz="0" iyy="0.02" iyz="0" izz="0.01"/>
    </inertial>
    <!--
    <visual name="l_wheel_dumb_visual">
      <geometry name="l_wheel_dumb_visual_geom">
        <cylinder radius="0.100" length="0.05" />
      </geometry>
      <origin rpy="1.570796 0 0" />
      <material name="lx_grey_mat">
        <color rgba="0.8 0.8 0.8 1.0" />
      </material>
    </visual>
   -->
    <collision name="l_wheel_collision">
      <geometry name="l_wheel_collision_geom">
        <cylinder length="0.05" radius="0.100"/>
      </geometry>
      <origin rpy="1.570796 0 0"/>
    </collision>
  </link>
  <!-- wheel joints. only used in gazebo, real robot velocity is controlled as a unit, not individual wheel motion. -->
  <joint name="r_wheel_joint" type="fixed">
    <!--  type="continuous" -->
    <origin rpy="0 0 0" xyz="0 0.2 0.1"/>
    <parent link="base_link"/>
    <child link="r_wheel"/>
  </joint>
  <joint name="l_wheel_joint" type="fixed">
    <!-- type="continuous" -->
    <origin rpy="0 0 0" xyz="0 -0.2 0.1"/>
    <parent link="base_link"/>
    <child link="l_wheel"/>
  </joint>
  <!-- pioneer lx deck -->
  <link name="deck">
    <visual name="deck_visual">
      <geometry name="deck_visual_geom">
        <box size="0.407 0.437 0.076"/>
      </geometry>
      <material name="lx_deck_mat">
        <color rgba="0 0 0 1"/>
      </material>
    </visual>
    <collision name="deck_collision">
      <geometry name="deck_collision_geom">
        <box size="0.407 0.437 0.076"/>
        <!-- box size="0.407 0.437 0.076" / -->
      </geometry>
    </collision>
  </link>
  <joint name="deck_joint" type="fixed">
    <origin rpy="0 0 0" xyz="0.075 0 0.410"/>
    <parent link="base_link"/>
    <child link="deck"/>
  </joint>
  <!-- "plinth" -->
  <link name="plinth">
    <visual name="plinth_visual">
      <geometry name="plinth_visual_geom">
        <mesh filename="package://amr_robots_description/meshes/pioneer-lx/pioneer-lx-plinth.stl" scale="0.001 0.001 0.001"/>
        <!-- box size="0.18 0.2476 0.99" / -->
      </geometry>
      <material name="plinth_darkgrey_mat">
        <color rgba="0.2 0.2 0.2 1.0"/>
      </material>
    </visual>
    <collision name="plinth_collision">
      <geometry name="plinth_collision_geom">
        <mesh filename="package://amr_robots_description/meshes/pioneer-lx/pioneer-lx-plinth.stl" scale="0.001 0.001 0.001"/>
        <!-- box size="0.18 0.2476 0.99" / -->
        <origin xyz="-0.02 0 0.867"/>
      </geometry>
    </collision>
  </link>
  <joint name="plinth_joint" type="fixed">
    <parent link="base_link"/>
    <child link="plinth"/>
    <origin xyz="-0.11 0 0.448"/>
  </joint>
  <!-- Jaco2 arms, using lower upward-pointing mounting option.

       The kinova_description package is contained in the
       Kinovarobotics jaco_ros repository. As of 2/4/2015, you must 
       check out the "jaco2_import" branch.
        https://github.com/Kinovarobotics/jaco-ros/tree/jaco2_import
   -->
  <!-- links      		mesh_no
   base           		0
   shoulder       		1
   arm            		2
   forearm        		3
   wrist          		4
   arm_mico       		5
   arm_half1 (7dof)		6
   arm_half2 (7dof)		7
   wrist_spherical_1  8
   wrist_spherical_2  9

   hand 3 finger  		55
   hand_2finger   		56
   finger_proximal		57
   finger_distal      58
-->
  <!-- links      		mesh_no
   base           		0
   shoulder       		1
   arm            		2
   forearm        		3
   wrist          		4
   arm_mico       		5
   arm_half1 (7dof)		6
   arm_half2 (7dof)		7
   wrist_spherical_1  8
   wrist_spherical_2  9

   hand 3 finger  		55
   hand_2finger   		56
   finger_proximal		57
   finger_distal      58
-->
  <link name="left_arm_mount">
  </link>
  <link name="right_arm_mount">
  </link>
  <joint name="left_arm_attach" type="fixed">
    <child link="left_arm_mount"/>
    <parent link="base_link"/>
    <origin rpy="0 0 1.5707" xyz="-0.02 0.184 1.086"/>
    <!-- old z was 1.1384 -->
  </joint>
  <joint name="right_arm_attach" type="fixed">
    <child link="right_arm_mount"/>
    <parent link="base_link"/>
    <origin rpy="0 0 1.5707" xyz="-0.02 -0.184 1.086"/>
    <!-- old z was 1.1384 -->
  </joint>
  <!-- ros_control plugin -->
  <gazebo>
    <plugin filename="libgazebo_ros_control.so" name="gazebo_ros_control">
      <robotNamespace>left</robotNamespace>
      <robotSimType>gazebo_ros_control/DefaultRobotHWSim</robotSimType>
      <legacyModeNS>true</legacyModeNS>
    </plugin>
  </gazebo>
  <link name="left_link_base">
    <visual>
      <geometry>
        <mesh filename="package://kinova_description/meshes/base.dae"/>
      </geometry>
      <material name="carbon_fiber">
        <color rgba="0.792156862745098 0.819607843137255 0.933333333333333 1"/>
      </material>
    </visual>
    <collision>
      <geometry>
        <mesh filename="package://kinova_description/meshes/base.dae"/>
      </geometry>
    </collision>
    <inertial>
      <mass value="0.46784"/>
      <origin rpy="0 0 0" xyz="0 0 0.1255"/>
      <inertia ixx="0.000951270861568" ixy="0" ixz="0" iyy="0.000951270861568" iyz="0" izz="0.000374272"/>
    </inertial>
  </link>
  <joint name="left_joint_base" type="fixed">
    <parent link="left_arm_mount"/>
    <child link="left_link_base"/>
    <axis xyz="0 0 0"/>
    <limit effort="0" lower="0" upper="0" velocity="0"/>
    <origin rpy="0 0 0" xyz="0 0 0"/>
    <dynamics damping="0.0" friction="0.0"/>
  </joint>
  <link name="left_link_1">
    <visual>
      <geometry>
        <mesh filename="package://kinova_description/meshes/shoulder.dae"/>
      </geometry>
      <material name="carbon_fiber">
        <color rgba="0.792156862745098 0.819607843137255 0.933333333333333 1"/>
      </material>
    </visual>
    <visual>
      <geometry>
        <mesh filename="package://kinova_description/meshes/ring_big.dae"/>
      </geometry>
    </visual>
    <collision>
      <geometry>
        <mesh filename="package://kinova_description/meshes/shoulder.dae"/>
      </geometry>
    </collision>
    <inertial>
      <mass value="0.7477"/>
      <origin xyz="0 -0.002 -0.0605"/>
      <inertia ixx="0.00152031725204" ixy="0" ixz="0" iyy="0.00152031725204" iyz="0" izz="0.00059816"/>
    </inertial>
  </link>
  <joint name="left_joint_1" type="continuous">
    <parent link="left_link_base"/>
    <child link="left_link_1"/>
    <axis xyz="0 0 1"/>
    <limit effort="40" lower="-6.28318530718" upper="6.28318530718" velocity="0.628318530718"/>
    <origin rpy="0 3.14159265359 0" xyz="0 0 0.15675"/>
    <dynamics damping="0.0" friction="0.0"/>
  </joint>
  <transmission name="left_joint_1_trans">
    <type>transmission_interface/SimpleTransmission</type>
    <joint name="left_joint_1">
      <hardwareInterface>hardware_interface/EffortJointInterface</hardwareInterface>
    </joint>
    <actuator name="left_joint_1_actuator">
      <hardwareInterface>hardware_interface/EffortJointInterface</hardwareInterface>
      <mechanicalReduction>160</mechanicalReduction>
    </actuator>
  </transmission>
  <!--For torque sensing in simulation-->
  <gazebo reference="left_joint_1">
    <provideFeedback>true</provideFeedback>
  </gazebo>
  <gazebo>
    <plugin filename="libgazebo_ros_ft_sensor.so" name="ft_sensor">
      <updateRate>30.0</updateRate>
      <topicName>left_joint_1_ft_sensor_topic</topicName>
      <jointName>left_joint_1</jointName>
    </plugin>
  </gazebo>
  <link name="left_link_2">
    <visual>
      <geometry>
        <mesh filename="package://kinova_description/meshes/arm.dae"/>
      </geometry>
      <material name="carbon_fiber">
        <color rgba="0.792156862745098 0.819607843137255 0.933333333333333 1"/>
      </material>
    </visual>
    <visual>
      <geometry>
        <mesh filename="package://kinova_description/meshes/ring_big.dae"/>
      </geometry>
    </visual>
    <collision>
      <geometry>
        <mesh filename="package://kinova_description/meshes/arm.dae"/>
      </geometry>
    </collision>
    <inertial>
      <mass value="0.99"/>
      <origin xyz="0 -0.2065 -0.01"/>
      <inertia ixx="0.010502207991" ixy="0" ixz="0" iyy="0.000792" iyz="0" izz="0.010502207991"/>
    </inertial>
  </link>
  <joint name="left_joint_2" type="revolute">
    <parent link="left_link_1"/>
    <child link="left_link_2"/>
    <axis xyz="0 0 1"/>
    <limit effort="80" lower="0.820304748437" upper="5.46288055874" velocity="0.628318530718"/>
    <origin rpy="-1.57079632679 0 3.14159265359" xyz="0 0.0016 -0.11875"/>
    <dynamics damping="0.0" friction="0.0"/>
  </joint>
  <transmission name="left_joint_2_trans">
    <type>transmission_interface/SimpleTransmission</type>
    <joint name="left_joint_2">
      <hardwareInterface>hardware_interface/EffortJointInterface</hardwareInterface>
    </joint>
    <actuator name="left_joint_2_actuator">
      <hardwareInterface>hardware_interface/EffortJointInterface</hardwareInterface>
      <mechanicalReduction>160</mechanicalReduction>
    </actuator>
  </transmission>
  <!--For torque sensing in simulation-->
  <gazebo reference="left_joint_2">
    <provideFeedback>true</provideFeedback>
  </gazebo>
  <gazebo>
    <plugin filename="libgazebo_ros_ft_sensor.so" name="ft_sensor">
      <updateRate>30.0</updateRate>
      <topicName>left_joint_2_ft_sensor_topic</topicName>
      <jointName>left_joint_2</jointName>
    </plugin>
  </gazebo>
  <link name="left_link_3">
    <visual>
      <geometry>
        <mesh filename="package://kinova_description/meshes/forearm.dae"/>
      </geometry>
      <material name="carbon_fiber">
        <color rgba="0.792156862745098 0.819607843137255 0.933333333333333 1"/>
      </material>
    </visual>
    <visual>
      <geometry>
        <mesh filename="package://kinova_description/meshes/ring_big.dae"/>
      </geometry>
    </visual>
    <collision>
      <geometry>
        <mesh filename="package://kinova_description/meshes/forearm.dae"/>
      </geometry>
    </collision>
    <inertial>
      <mass value="0.6763"/>
      <origin xyz="0 0.081 -0.0086"/>
      <inertia ixx="0.00142022431908" ixy="0" ixz="0" iyy="0.000304335" iyz="0" izz="0.00142022431908"/>
    </inertial>
  </link>
  <joint name="left_joint_3" type="revolute">
    <parent link="left_link_2"/>
    <child link="left_link_3"/>
    <axis xyz="0 0 1"/>
    <limit effort="40" lower="0.331612557879" upper="5.9515727493" velocity="0.628318530718"/>
    <origin rpy="0 3.14159265359 0" xyz="0 -0.410 0"/>
    <dynamics damping="0.0" friction="0.0"/>
  </joint>
  <transmission name="left_joint_3_trans">
    <type>transmission_interface/SimpleTransmission</type>
    <joint name="left_joint_3">
      <hardwareInterface>hardware_interface/EffortJointInterface</hardwareInterface>
    </joint>
    <actuator name="left_joint_3_actuator">
      <hardwareInterface>hardware_interface/EffortJointInterface</hardwareInterface>
      <mechanicalReduction>160</mechanicalReduction>
    </actuator>
  </transmission>
  <!--For torque sensing in simulation-->
  <gazebo reference="left_joint_3">
    <provideFeedback>true</provideFeedback>
  </gazebo>
  <gazebo>
    <plugin filename="libgazebo_ros_ft_sensor.so" name="ft_sensor">
      <updateRate>30.0</updateRate>
      <topicName>left_joint_3_ft_sensor_topic</topicName>
      <jointName>left_joint_3</jointName>
    </plugin>
  </gazebo>
  <link name="left_link_4">
    <visual>
      <geometry>
        <mesh filename="package://kinova_description/meshes/wrist.dae"/>
      </geometry>
      <material name="carbon_fiber">
        <color rgba="0.792156862745098 0.819607843137255 0.933333333333333 1"/>
      </material>
    </visual>
    <visual>
      <geometry>
        <mesh filename="package://kinova_description/meshes/ring_small.dae"/>
      </geometry>
    </visual>
    <collision>
      <geometry>
        <mesh filename="package://kinova_description/meshes/wrist.dae"/>
      </geometry>
    </collision>
    <inertial>
      <mass value="0.426367"/>
      <origin xyz="0 -0.037 -0.0642"/>
      <inertia ixx="7.73496906e-05" ixy="0" ixz="0" iyy="7.73496906e-05" iyz="0" izz="0.0001428"/>
    </inertial>
  </link>
  <joint name="left_joint_4" type="continuous">
    <parent link="left_link_3"/>
    <child link="left_link_4"/>
    <axis xyz="0 0 1"/>
    <limit effort="20" lower="-6.28318530718" upper="6.28318530718" velocity="0.837758040957"/>
    <origin rpy="-1.57079632679 0 3.14159265359" xyz="0 0.2073 -0.0114"/>
    <dynamics damping="0.0" friction="0.0"/>
  </joint>
  <transmission name="left_joint_4_trans">
    <type>transmission_interface/SimpleTransmission</type>
    <joint name="left_joint_4">
      <hardwareInterface>hardware_interface/EffortJointInterface</hardwareInterface>
    </joint>
    <actuator name="left_joint_4_actuator">
      <hardwareInterface>hardware_interface/EffortJointInterface</hardwareInterface>
      <mechanicalReduction>160</mechanicalReduction>
    </actuator>
  </transmission>
  <!--For torque sensing in simulation-->
  <gazebo reference="left_joint_4">
    <provideFeedback>true</provideFeedback>
  </gazebo>
  <gazebo>
    <plugin filename="libgazebo_ros_ft_sensor.so" name="ft_sensor">
      <updateRate>30.0</updateRate>
      <topicName>left_joint_4_ft_sensor_topic</topicName>
      <jointName>left_joint_4</jointName>
    </plugin>
  </gazebo>
  <link name="left_link_5">
    <visual>
      <geometry>
        <mesh filename="package://kinova_description/meshes/wrist.dae"/>
      </geometry>
      <material name="carbon_fiber">
        <color rgba="0.792156862745098 0.819607843137255 0.933333333333333 1"/>
      </material>
    </visual>
    <visual>
      <geometry>
        <mesh filename="package://kinova_description/meshes/ring_small.dae"/>
      </geometry>
    </visual>
    <collision>
      <geometry>
        <mesh filename="package://kinova_description/meshes/wrist.dae"/>
      </geometry>
    </collision>
    <inertial>
      <mass value="0.426367"/>
      <origin xyz="0 -0.037 -0.0642"/>
      <inertia ixx="7.73496906e-05" ixy="0" ixz="0" iyy="7.73496906e-05" iyz="0" izz="0.0001428"/>
    </inertial>
  </link>
  <joint name="left_joint_5" type="continuous">
    <parent link="left_link_4"/>
    <child link="left_link_5"/>
    <axis xyz="0 0 1"/>
    <limit effort="20" lower="-6.28318530718" upper="6.28318530718" velocity="0.837758040957"/>
    <origin rpy="1.0471975512 0 3.14159265359" xyz="0 -0.03703 -0.06414"/>
    <dynamics damping="0.0" friction="0.0"/>
  </joint>
  <transmission name="left_joint_5_trans">
    <type>transmission_interface/SimpleTransmission</type>
    <joint name="left_joint_5">
      <hardwareInterface>hardware_interface/EffortJointInterface</hardwareInterface>
    </joint>
    <actuator name="left_joint_5_actuator">
      <hardwareInterface>hardware_interface/EffortJointInterface</hardwareInterface>
      <mechanicalReduction>160</mechanicalReduction>
    </actuator>
  </transmission>
  <!--For torque sensing in simulation-->
  <gazebo reference="left_joint_5">
    <provideFeedback>true</provideFeedback>
  </gazebo>
  <gazebo>
    <plugin filename="libgazebo_ros_ft_sensor.so" name="ft_sensor">
      <updateRate>30.0</updateRate>
      <topicName>left_joint_5_ft_sensor_topic</topicName>
      <jointName>left_joint_5</jointName>
    </plugin>
  </gazebo>
  <link name="left_link_6">
    <visual>
      <geometry>
        <mesh filename="package://kinova_description/meshes/hand_3finger.dae"/>
      </geometry>
      <material name="carbon_fiber">
        <color rgba="0.792156862745098 0.819607843137255 0.933333333333333 1"/>
      </material>
    </visual>
    <visual>
      <geometry>
        <mesh filename="package://kinova_description/meshes/ring_small.dae"/>
      </geometry>
    </visual>
    <collision>
      <geometry>
        <mesh filename="package://kinova_description/meshes/hand_3finger.dae"/>
      </geometry>
    </collision>
    <inertial>
      <mass value="0.99"/>
      <origin xyz="0 0 -0.06"/>
      <inertia ixx="0.0003453236187" ixy="0" ixz="0" iyy="0.0003453236187" iyz="0" izz="0.0005816"/>
    </inertial>
  </link>
  <joint name="left_joint_6" type="continuous">
    <parent link="left_link_5"/>
    <child link="left_link_6"/>
    <axis xyz="0 0 1"/>
    <limit effort="20" lower="-6.28318530718" upper="6.28318530718" velocity="0.837758040957"/>
    <origin rpy="1.0471975512 0 3.14159265359" xyz="0 -0.03703 -0.06414"/>
    <dynamics damping="0.0" friction="0.0"/>
  </joint>
  <transmission name="left_joint_6_trans">
    <type>transmission_interface/SimpleTransmission</type>
    <joint name="left_joint_6">
      <hardwareInterface>hardware_interface/EffortJointInterface</hardwareInterface>
    </joint>
    <actuator name="left_joint_6_actuator">
      <hardwareInterface>hardware_interface/EffortJointInterface</hardwareInterface>
      <mechanicalReduction>160</mechanicalReduction>
    </actuator>
  </transmission>
  <!--For torque sensing in simulation-->
  <gazebo reference="left_joint_6">
    <provideFeedback>true</provideFeedback>
  </gazebo>
  <gazebo>
    <plugin filename="libgazebo_ros_ft_sensor.so" name="ft_sensor">
      <updateRate>30.0</updateRate>
      <topicName>left_joint_6_ft_sensor_topic</topicName>
      <jointName>left_joint_6</jointName>
    </plugin>
  </gazebo>
  <link name="left_end_effector"/>
  <joint name="left_joint_end_effector" type="fixed">
    <parent link="left_link_6"/>
    <child link="left_end_effector"/>
    <axis xyz="0 0 0"/>
    <limit effort="2000" lower="0" upper="0" velocity="1"/>
    <origin rpy="3.14159265359 0 1.57079632679" xyz="0 0 -0.1600"/>
  </joint>
  <link name="left_link_finger_1">
    <visual>
      <geometry>
        <mesh filename="package://kinova_description/meshes/finger_proximal.dae"/>
      </geometry>
      <material name="carbon_fiber">
        <color rgba="0.792156862745098 0.819607843137255 0.933333333333333 1"/>
      </material>
    </visual>
    <collision>
      <geometry>
        <mesh filename="package://kinova_description/meshes/finger_proximal.dae"/>
      </geometry>
    </collision>
    <inertial>
      <mass value="0.01"/>
      <origin xyz="0.022 0 0"/>
      <inertia ixx="7.8999684e-07" ixy="0" ixz="0" iyy="7.8999684e-07" iyz="0" izz="8e-08"/>
    </inertial>
  </link>
  <joint name="left_joint_finger_1" type="revolute">
    <parent link="left_link_6"/>
    <child link="left_link_finger_1"/>
    <axis xyz="0 0 1"/>
    <origin rpy="-1.570796327 .649262481663582 1.35961148639407" xyz="0.00279 0.03126 -0.11467"/>
    <limit effort="2" lower="0" upper="1.51" velocity="1"/>
  </joint>
  <transmission name="left_joint_finger_1_trans">
    <type>transmission_interface/SimpleTransmission</type>
    <joint name="left_joint_finger_1">
      <hardwareInterface>hardware_interface/EffortJointInterface</hardwareInterface>
    </joint>
    <actuator name="left_joint_finger_1_actuator">
      <hardwareInterface>hardware_interface/EffortJointInterface</hardwareInterface>
      <mechanicalReduction>1</mechanicalReduction>
    </actuator>
  </transmission>
  <link name="left_link_finger_tip_1">
    <visual>
      <geometry>
        <mesh filename="package://kinova_description/meshes/finger_distal.dae"/>
      </geometry>
      <material name="carbon_fiber">
        <color rgba="0.792156862745098 0.819607843137255 0.933333333333333 1"/>
      </material>
    </visual>
    <collision>
      <geometry>
        <mesh filename="package://kinova_description/meshes/finger_distal.dae"/>
      </geometry>
    </collision>
    <inertial>
      <mass value="0.01"/>
      <origin xyz="0.022 0 0"/>
      <inertia ixx="7.8999684e-07" ixy="0" ixz="0" iyy="7.8999684e-07" iyz="0" izz="8e-08"/>
    </inertial>
  </link>
  <joint name="left_joint_finger_tip_1" type="revolute">
    <parent link="left_link_finger_1"/>
    <child link="left_link_finger_tip_1"/>
    <axis xyz="0 0 1"/>
    <origin rpy="0 0 0" xyz="0.044 -0.003 0"/>
    <limit effort="2" lower="0" upper="2" velocity="1"/>
  </joint>
  <transmission name="left_joint_finger_tip_1_trans">
    <type>transmission_interface/SimpleTransmission</type>
    <joint name="left_joint_finger_tip_1">
      <hardwareInterface>hardware_interface/EffortJointInterface</hardwareInterface>
    </joint>
    <actuator name="left_joint_finger_tip_1_actuator">
      <hardwareInterface>hardware_interface/EffortJointInterface</hardwareInterface>
      <mechanicalReduction>1</mechanicalReduction>
    </actuator>
  </transmission>
  <link name="left_link_finger_2">
    <visual>
      <geometry>
        <mesh filename="package://kinova_description/meshes/finger_proximal.dae"/>
      </geometry>
      <material name="carbon_fiber">
        <color rgba="0.792156862745098 0.819607843137255 0.933333333333333 1"/>
      </material>
    </visual>
    <collision>
      <geometry>
        <mesh filename="package://kinova_description/meshes/finger_proximal.dae"/>
      </geometry>
    </collision>
    <inertial>
      <mass value="0.01"/>
      <origin xyz="0.022 0 0"/>
      <inertia ixx="7.8999684e-07" ixy="0" ixz="0" iyy="7.8999684e-07" iyz="0" izz="8e-08"/>
    </inertial>
  </link>
  <joint name="left_joint_finger_2" type="revolute">
    <parent link="left_link_6"/>
    <child link="left_link_finger_2"/>
    <axis xyz="0 0 1"/>
    <origin rpy="-1.570796327 .649262481663582 -1.38614049188413" xyz="0.02226 -0.02707 -0.11482"/>
    <limit effort="2" lower="0" upper="1.51" velocity="1"/>
  </joint>
  <transmission name="left_joint_finger_2_trans">
    <type>transmission_interface/SimpleTransmission</type>
    <joint name="left_joint_finger_2">
      <hardwareInterface>hardware_interface/EffortJointInterface</hardwareInterface>
    </joint>
    <actuator name="left_joint_finger_2_actuator">
      <hardwareInterface>hardware_interface/EffortJointInterface</hardwareInterface>
      <mechanicalReduction>1</mechanicalReduction>
    </actuator>
  </transmission>
  <link name="left_link_finger_tip_2">
    <visual>
      <geometry>
        <mesh filename="package://kinova_description/meshes/finger_distal.dae"/>
      </geometry>
      <material name="carbon_fiber">
        <color rgba="0.792156862745098 0.819607843137255 0.933333333333333 1"/>
      </material>
    </visual>
    <collision>
      <geometry>
        <mesh filename="package://kinova_description/meshes/finger_distal.dae"/>
      </geometry>
    </collision>
    <inertial>
      <mass value="0.01"/>
      <origin xyz="0.022 0 0"/>
      <inertia ixx="7.8999684e-07" ixy="0" ixz="0" iyy="7.8999684e-07" iyz="0" izz="8e-08"/>
    </inertial>
  </link>
  <joint name="left_joint_finger_tip_2" type="revolute">
    <parent link="left_link_finger_2"/>
    <child link="left_link_finger_tip_2"/>
    <axis xyz="0 0 1"/>
    <origin rpy="0 0 0" xyz="0.044 -0.003 0"/>
    <limit effort="2" lower="0" upper="2" velocity="1"/>
  </joint>
  <transmission name="left_joint_finger_tip_2_trans">
    <type>transmission_interface/SimpleTransmission</type>
    <joint name="left_joint_finger_tip_2">
      <hardwareInterface>hardware_interface/EffortJointInterface</hardwareInterface>
    </joint>
    <actuator name="left_joint_finger_tip_2_actuator">
      <hardwareInterface>hardware_interface/EffortJointInterface</hardwareInterface>
      <mechanicalReduction>1</mechanicalReduction>
    </actuator>
  </transmission>
  <link name="left_link_finger_3">
    <visual>
      <geometry>
        <mesh filename="package://kinova_description/meshes/finger_proximal.dae"/>
      </geometry>
      <material name="carbon_fiber">
        <color rgba="0.792156862745098 0.819607843137255 0.933333333333333 1"/>
      </material>
    </visual>
    <collision>
      <geometry>
        <mesh filename="package://kinova_description/meshes/finger_proximal.dae"/>
      </geometry>
    </collision>
    <inertial>
      <mass value="0.01"/>
      <origin xyz="0.022 0 0"/>
      <inertia ixx="7.8999684e-07" ixy="0" ixz="0" iyy="7.8999684e-07" iyz="0" izz="8e-08"/>
    </inertial>
  </link>
  <joint name="left_joint_finger_3" type="revolute">
    <parent link="left_link_6"/>
    <child link="left_link_finger_3"/>
    <axis xyz="0 0 1"/>
    <origin rpy="-1.570796327 .649262481663582 -1.75545216211587" xyz="-0.02226 -0.02707 -0.11482"/>
    <limit effort="2" lower="0" upper="1.51" velocity="1"/>
  </joint>
  <transmission name="left_joint_finger_3_trans">
    <type>transmission_interface/SimpleTransmission</type>
    <joint name="left_joint_finger_3">
      <hardwareInterface>hardware_interface/EffortJointInterface</hardwareInterface>
    </joint>
    <actuator name="left_joint_finger_3_actuator">
      <hardwareInterface>hardware_interface/EffortJointInterface</hardwareInterface>
      <mechanicalReduction>1</mechanicalReduction>
    </actuator>
  </transmission>
  <link name="left_link_finger_tip_3">
    <visual>
      <geometry>
        <mesh filename="package://kinova_description/meshes/finger_distal.dae"/>
      </geometry>
      <material name="carbon_fiber">
        <color rgba="0.792156862745098 0.819607843137255 0.933333333333333 1"/>
      </material>
    </visual>
    <collision>
      <geometry>
        <mesh filename="package://kinova_description/meshes/finger_distal.dae"/>
      </geometry>
    </collision>
    <inertial>
      <mass value="0.01"/>
      <origin xyz="0.022 0 0"/>
      <inertia ixx="7.8999684e-07" ixy="0" ixz="0" iyy="7.8999684e-07" iyz="0" izz="8e-08"/>
    </inertial>
  </link>
  <joint name="left_joint_finger_tip_3" type="revolute">
    <parent link="left_link_finger_3"/>
    <child link="left_link_finger_tip_3"/>
    <axis xyz="0 0 1"/>
    <origin rpy="0 0 0" xyz="0.044 -0.003 0"/>
    <limit effort="2" lower="0" upper="2" velocity="1"/>
  </joint>
  <transmission name="left_joint_finger_tip_3_trans">
    <type>transmission_interface/SimpleTransmission</type>
    <joint name="left_joint_finger_tip_3">
      <hardwareInterface>hardware_interface/EffortJointInterface</hardwareInterface>
    </joint>
    <actuator name="left_joint_finger_tip_3_actuator">
      <hardwareInterface>hardware_interface/EffortJointInterface</hardwareInterface>
      <mechanicalReduction>1</mechanicalReduction>
    </actuator>
  </transmission>
  <!-- ros_control plugin -->
  <gazebo>
    <plugin filename="libgazebo_ros_control.so" name="gazebo_ros_control">
      <robotNamespace>right</robotNamespace>
      <robotSimType>gazebo_ros_control/DefaultRobotHWSim</robotSimType>
      <legacyModeNS>true</legacyModeNS>
    </plugin>
  </gazebo>
  <link name="right_link_base">
    <visual>
      <geometry>
        <mesh filename="package://kinova_description/meshes/base.dae"/>
      </geometry>
      <material name="carbon_fiber">
        <color rgba="0.792156862745098 0.819607843137255 0.933333333333333 1"/>
      </material>
    </visual>
    <collision>
      <geometry>
        <mesh filename="package://kinova_description/meshes/base.dae"/>
      </geometry>
    </collision>
    <inertial>
      <mass value="0.46784"/>
      <origin rpy="0 0 0" xyz="0 0 0.1255"/>
      <inertia ixx="0.000951270861568" ixy="0" ixz="0" iyy="0.000951270861568" iyz="0" izz="0.000374272"/>
    </inertial>
  </link>
  <joint name="right_joint_base" type="fixed">
    <parent link="right_arm_mount"/>
    <child link="right_link_base"/>
    <axis xyz="0 0 0"/>
    <limit effort="0" lower="0" upper="0" velocity="0"/>
    <origin rpy="0 0 0" xyz="0 0 0"/>
    <dynamics damping="0.0" friction="0.0"/>
  </joint>
  <link name="right_link_1">
    <visual>
      <geometry>
        <mesh filename="package://kinova_description/meshes/shoulder.dae"/>
      </geometry>
      <material name="carbon_fiber">
        <color rgba="0.792156862745098 0.819607843137255 0.933333333333333 1"/>
      </material>
    </visual>
    <visual>
      <geometry>
        <mesh filename="package://kinova_description/meshes/ring_big.dae"/>
      </geometry>
    </visual>
    <collision>
      <geometry>
        <mesh filename="package://kinova_description/meshes/shoulder.dae"/>
      </geometry>
    </collision>
    <inertial>
      <mass value="0.7477"/>
      <origin xyz="0 -0.002 -0.0605"/>
      <inertia ixx="0.00152031725204" ixy="0" ixz="0" iyy="0.00152031725204" iyz="0" izz="0.00059816"/>
    </inertial>
  </link>
  <joint name="right_joint_1" type="continuous">
    <parent link="right_link_base"/>
    <child link="right_link_1"/>
    <axis xyz="0 0 1"/>
    <limit effort="40" lower="-6.28318530718" upper="6.28318530718" velocity="0.628318530718"/>
    <origin rpy="0 3.14159265359 0" xyz="0 0 0.15675"/>
    <dynamics damping="0.0" friction="0.0"/>
  </joint>
  <transmission name="right_joint_1_trans">
    <type>transmission_interface/SimpleTransmission</type>
    <joint name="right_joint_1">
      <hardwareInterface>hardware_interface/EffortJointInterface</hardwareInterface>
    </joint>
    <actuator name="right_joint_1_actuator">
      <hardwareInterface>hardware_interface/EffortJointInterface</hardwareInterface>
      <mechanicalReduction>160</mechanicalReduction>
    </actuator>
  </transmission>
  <!--For torque sensing in simulation-->
  <gazebo reference="right_joint_1">
    <provideFeedback>true</provideFeedback>
  </gazebo>
  <gazebo>
    <plugin filename="libgazebo_ros_ft_sensor.so" name="ft_sensor">
      <updateRate>30.0</updateRate>
      <topicName>right_joint_1_ft_sensor_topic</topicName>
      <jointName>right_joint_1</jointName>
    </plugin>
  </gazebo>
  <link name="right_link_2">
    <visual>
      <geometry>
        <mesh filename="package://kinova_description/meshes/arm.dae"/>
      </geometry>
      <material name="carbon_fiber">
        <color rgba="0.792156862745098 0.819607843137255 0.933333333333333 1"/>
      </material>
    </visual>
    <visual>
      <geometry>
        <mesh filename="package://kinova_description/meshes/ring_big.dae"/>
      </geometry>
    </visual>
    <collision>
      <geometry>
        <mesh filename="package://kinova_description/meshes/arm.dae"/>
      </geometry>
    </collision>
    <inertial>
      <mass value="0.99"/>
      <origin xyz="0 -0.2065 -0.01"/>
      <inertia ixx="0.010502207991" ixy="0" ixz="0" iyy="0.000792" iyz="0" izz="0.010502207991"/>
    </inertial>
  </link>
  <joint name="right_joint_2" type="revolute">
    <parent link="right_link_1"/>
    <child link="right_link_2"/>
    <axis xyz="0 0 1"/>
    <limit effort="80" lower="0.820304748437" upper="5.46288055874" velocity="0.628318530718"/>
    <origin rpy="-1.57079632679 0 3.14159265359" xyz="0 0.0016 -0.11875"/>
    <dynamics damping="0.0" friction="0.0"/>
  </joint>
  <transmission name="right_joint_2_trans">
    <type>transmission_interface/SimpleTransmission</type>
    <joint name="right_joint_2">
      <hardwareInterface>hardware_interface/EffortJointInterface</hardwareInterface>
    </joint>
    <actuator name="right_joint_2_actuator">
      <hardwareInterface>hardware_interface/EffortJointInterface</hardwareInterface>
      <mechanicalReduction>160</mechanicalReduction>
    </actuator>
  </transmission>
  <!--For torque sensing in simulation-->
  <gazebo reference="right_joint_2">
    <provideFeedback>true</provideFeedback>
  </gazebo>
  <gazebo>
    <plugin filename="libgazebo_ros_ft_sensor.so" name="ft_sensor">
      <updateRate>30.0</updateRate>
      <topicName>right_joint_2_ft_sensor_topic</topicName>
      <jointName>right_joint_2</jointName>
    </plugin>
  </gazebo>
  <link name="right_link_3">
    <visual>
      <geometry>
        <mesh filename="package://kinova_description/meshes/forearm.dae"/>
      </geometry>
      <material name="carbon_fiber">
        <color rgba="0.792156862745098 0.819607843137255 0.933333333333333 1"/>
      </material>
    </visual>
    <visual>
      <geometry>
        <mesh filename="package://kinova_description/meshes/ring_big.dae"/>
      </geometry>
    </visual>
    <collision>
      <geometry>
        <mesh filename="package://kinova_description/meshes/forearm.dae"/>
      </geometry>
    </collision>
    <inertial>
      <mass value="0.6763"/>
      <origin xyz="0 0.081 -0.0086"/>
      <inertia ixx="0.00142022431908" ixy="0" ixz="0" iyy="0.000304335" iyz="0" izz="0.00142022431908"/>
    </inertial>
  </link>
  <joint name="right_joint_3" type="revolute">
    <parent link="right_link_2"/>
    <child link="right_link_3"/>
    <axis xyz="0 0 1"/>
    <limit effort="40" lower="0.331612557879" upper="5.9515727493" velocity="0.628318530718"/>
    <origin rpy="0 3.14159265359 0" xyz="0 -0.410 0"/>
    <dynamics damping="0.0" friction="0.0"/>
  </joint>
  <transmission name="right_joint_3_trans">
    <type>transmission_interface/SimpleTransmission</type>
    <joint name="right_joint_3">
      <hardwareInterface>hardware_interface/EffortJointInterface</hardwareInterface>
    </joint>
    <actuator name="right_joint_3_actuator">
      <hardwareInterface>hardware_interface/EffortJointInterface</hardwareInterface>
      <mechanicalReduction>160</mechanicalReduction>
    </actuator>
  </transmission>
  <!--For torque sensing in simulation-->
  <gazebo reference="right_joint_3">
    <provideFeedback>true</provideFeedback>
  </gazebo>
  <gazebo>
    <plugin filename="libgazebo_ros_ft_sensor.so" name="ft_sensor">
      <updateRate>30.0</updateRate>
      <topicName>right_joint_3_ft_sensor_topic</topicName>
      <jointName>right_joint_3</jointName>
    </plugin>
  </gazebo>
  <link name="right_link_4">
    <visual>
      <geometry>
        <mesh filename="package://kinova_description/meshes/wrist.dae"/>
      </geometry>
      <material name="carbon_fiber">
        <color rgba="0.792156862745098 0.819607843137255 0.933333333333333 1"/>
      </material>
    </visual>
    <visual>
      <geometry>
        <mesh filename="package://kinova_description/meshes/ring_small.dae"/>
      </geometry>
    </visual>
    <collision>
      <geometry>
        <mesh filename="package://kinova_description/meshes/wrist.dae"/>
      </geometry>
    </collision>
    <inertial>
      <mass value="0.426367"/>
      <origin xyz="0 -0.037 -0.0642"/>
      <inertia ixx="7.73496906e-05" ixy="0" ixz="0" iyy="7.73496906e-05" iyz="0" izz="0.0001428"/>
    </inertial>
  </link>
  <joint name="right_joint_4" type="continuous">
    <parent link="right_link_3"/>
    <child link="right_link_4"/>
    <axis xyz="0 0 1"/>
    <limit effort="20" lower="-6.28318530718" upper="6.28318530718" velocity="0.837758040957"/>
    <origin rpy="-1.57079632679 0 3.14159265359" xyz="0 0.2073 -0.0114"/>
    <dynamics damping="0.0" friction="0.0"/>
  </joint>
  <transmission name="right_joint_4_trans">
    <type>transmission_interface/SimpleTransmission</type>
    <joint name="right_joint_4">
      <hardwareInterface>hardware_interface/EffortJointInterface</hardwareInterface>
    </joint>
    <actuator name="right_joint_4_actuator">
      <hardwareInterface>hardware_interface/EffortJointInterface</hardwareInterface>
      <mechanicalReduction>160</mechanicalReduction>
    </actuator>
  </transmission>
  <!--For torque sensing in simulation-->
  <gazebo reference="right_joint_4">
    <provideFeedback>true</provideFeedback>
  </gazebo>
  <gazebo>
    <plugin filename="libgazebo_ros_ft_sensor.so" name="ft_sensor">
      <updateRate>30.0</updateRate>
      <topicName>right_joint_4_ft_sensor_topic</topicName>
      <jointName>right_joint_4</jointName>
    </plugin>
  </gazebo>
  <link name="right_link_5">
    <visual>
      <geometry>
        <mesh filename="package://kinova_description/meshes/wrist.dae"/>
      </geometry>
      <material name="carbon_fiber">
        <color rgba="0.792156862745098 0.819607843137255 0.933333333333333 1"/>
      </material>
    </visual>
    <visual>
      <geometry>
        <mesh filename="package://kinova_description/meshes/ring_small.dae"/>
      </geometry>
    </visual>
    <collision>
      <geometry>
        <mesh filename="package://kinova_description/meshes/wrist.dae"/>
      </geometry>
    </collision>
    <inertial>
      <mass value="0.426367"/>
      <origin xyz="0 -0.037 -0.0642"/>
      <inertia ixx="7.73496906e-05" ixy="0" ixz="0" iyy="7.73496906e-05" iyz="0" izz="0.0001428"/>
    </inertial>
  </link>
  <joint name="right_joint_5" type="continuous">
    <parent link="right_link_4"/>
    <child link="right_link_5"/>
    <axis xyz="0 0 1"/>
    <limit effort="20" lower="-6.28318530718" upper="6.28318530718" velocity="0.837758040957"/>
    <origin rpy="1.0471975512 0 3.14159265359" xyz="0 -0.03703 -0.06414"/>
    <dynamics damping="0.0" friction="0.0"/>
  </joint>
  <transmission name="right_joint_5_trans">
    <type>transmission_interface/SimpleTransmission</type>
    <joint name="right_joint_5">
      <hardwareInterface>hardware_interface/EffortJointInterface</hardwareInterface>
    </joint>
    <actuator name="right_joint_5_actuator">
      <hardwareInterface>hardware_interface/EffortJointInterface</hardwareInterface>
      <mechanicalReduction>160</mechanicalReduction>
    </actuator>
  </transmission>
  <!--For torque sensing in simulation-->
  <gazebo reference="right_joint_5">
    <provideFeedback>true</provideFeedback>
  </gazebo>
  <gazebo>
    <plugin filename="libgazebo_ros_ft_sensor.so" name="ft_sensor">
      <updateRate>30.0</updateRate>
      <topicName>right_joint_5_ft_sensor_topic</topicName>
      <jointName>right_joint_5</jointName>
    </plugin>
  </gazebo>
  <link name="right_link_6">
    <visual>
      <geometry>
        <mesh filename="package://kinova_description/meshes/hand_3finger.dae"/>
      </geometry>
      <material name="carbon_fiber">
        <color rgba="0.792156862745098 0.819607843137255 0.933333333333333 1"/>
      </material>
    </visual>
    <visual>
      <geometry>
        <mesh filename="package://kinova_description/meshes/ring_small.dae"/>
      </geometry>
    </visual>
    <collision>
      <geometry>
        <mesh filename="package://kinova_description/meshes/hand_3finger.dae"/>
      </geometry>
    </collision>
    <inertial>
      <mass value="0.99"/>
      <origin xyz="0 0 -0.06"/>
      <inertia ixx="0.0003453236187" ixy="0" ixz="0" iyy="0.0003453236187" iyz="0" izz="0.0005816"/>
    </inertial>
  </link>
  <joint name="right_joint_6" type="continuous">
    <parent link="right_link_5"/>
    <child link="right_link_6"/>
    <axis xyz="0 0 1"/>
    <limit effort="20" lower="-6.28318530718" upper="6.28318530718" velocity="0.837758040957"/>
    <origin rpy="1.0471975512 0 3.14159265359" xyz="0 -0.03703 -0.06414"/>
    <dynamics damping="0.0" friction="0.0"/>
  </joint>
  <transmission name="right_joint_6_trans">
    <type>transmission_interface/SimpleTransmission</type>
    <joint name="right_joint_6">
      <hardwareInterface>hardware_interface/EffortJointInterface</hardwareInterface>
    </joint>
    <actuator name="right_joint_6_actuator">
      <hardwareInterface>hardware_interface/EffortJointInterface</hardwareInterface>
      <mechanicalReduction>160</mechanicalReduction>
    </actuator>
  </transmission>
  <!--For torque sensing in simulation-->
  <gazebo reference="right_joint_6">
    <provideFeedback>true</provideFeedback>
  </gazebo>
  <gazebo>
    <plugin filename="libgazebo_ros_ft_sensor.so" name="ft_sensor">
      <updateRate>30.0</updateRate>
      <topicName>right_joint_6_ft_sensor_topic</topicName>
      <jointName>right_joint_6</jointName>
    </plugin>
  </gazebo>
  <link name="right_end_effector"/>
  <joint name="right_joint_end_effector" type="fixed">
    <parent link="right_link_6"/>
    <child link="right_end_effector"/>
    <axis xyz="0 0 0"/>
    <limit effort="2000" lower="0" upper="0" velocity="1"/>
    <origin rpy="3.14159265359 0 1.57079632679" xyz="0 0 -0.1600"/>
  </joint>
  <link name="right_link_finger_1">
    <visual>
      <geometry>
        <mesh filename="package://kinova_description/meshes/finger_proximal.dae"/>
      </geometry>
      <material name="carbon_fiber">
        <color rgba="0.792156862745098 0.819607843137255 0.933333333333333 1"/>
      </material>
    </visual>
    <collision>
      <geometry>
        <mesh filename="package://kinova_description/meshes/finger_proximal.dae"/>
      </geometry>
    </collision>
    <inertial>
      <mass value="0.01"/>
      <origin xyz="0.022 0 0"/>
      <inertia ixx="7.8999684e-07" ixy="0" ixz="0" iyy="7.8999684e-07" iyz="0" izz="8e-08"/>
    </inertial>
  </link>
  <joint name="right_joint_finger_1" type="revolute">
    <parent link="right_link_6"/>
    <child link="right_link_finger_1"/>
    <axis xyz="0 0 1"/>
    <origin rpy="-1.570796327 .649262481663582 1.35961148639407" xyz="0.00279 0.03126 -0.11467"/>
    <limit effort="2" lower="0" upper="1.51" velocity="1"/>
  </joint>
  <transmission name="right_joint_finger_1_trans">
    <type>transmission_interface/SimpleTransmission</type>
    <joint name="right_joint_finger_1">
      <hardwareInterface>hardware_interface/EffortJointInterface</hardwareInterface>
    </joint>
    <actuator name="right_joint_finger_1_actuator">
      <hardwareInterface>hardware_interface/EffortJointInterface</hardwareInterface>
      <mechanicalReduction>1</mechanicalReduction>
    </actuator>
  </transmission>
  <link name="right_link_finger_tip_1">
    <visual>
      <geometry>
        <mesh filename="package://kinova_description/meshes/finger_distal.dae"/>
      </geometry>
      <material name="carbon_fiber">
        <color rgba="0.792156862745098 0.819607843137255 0.933333333333333 1"/>
      </material>
    </visual>
    <collision>
      <geometry>
        <mesh filename="package://kinova_description/meshes/finger_distal.dae"/>
      </geometry>
    </collision>
    <inertial>
      <mass value="0.01"/>
      <origin xyz="0.022 0 0"/>
      <inertia ixx="7.8999684e-07" ixy="0" ixz="0" iyy="7.8999684e-07" iyz="0" izz="8e-08"/>
    </inertial>
  </link>
  <joint name="right_joint_finger_tip_1" type="revolute">
    <parent link="right_link_finger_1"/>
    <child link="right_link_finger_tip_1"/>
    <axis xyz="0 0 1"/>
    <origin rpy="0 0 0" xyz="0.044 -0.003 0"/>
    <limit effort="2" lower="0" upper="2" velocity="1"/>
  </joint>
  <transmission name="right_joint_finger_tip_1_trans">
    <type>transmission_interface/SimpleTransmission</type>
    <joint name="right_joint_finger_tip_1">
      <hardwareInterface>hardware_interface/EffortJointInterface</hardwareInterface>
    </joint>
    <actuator name="right_joint_finger_tip_1_actuator">
      <hardwareInterface>hardware_interface/EffortJointInterface</hardwareInterface>
      <mechanicalReduction>1</mechanicalReduction>
    </actuator>
  </transmission>
  <link name="right_link_finger_2">
    <visual>
      <geometry>
        <mesh filename="package://kinova_description/meshes/finger_proximal.dae"/>
      </geometry>
      <material name="carbon_fiber">
        <color rgba="0.792156862745098 0.819607843137255 0.933333333333333 1"/>
      </material>
    </visual>
    <collision>
      <geometry>
        <mesh filename="package://kinova_description/meshes/finger_proximal.dae"/>
      </geometry>
    </collision>
    <inertial>
      <mass value="0.01"/>
      <origin xyz="0.022 0 0"/>
      <inertia ixx="7.8999684e-07" ixy="0" ixz="0" iyy="7.8999684e-07" iyz="0" izz="8e-08"/>
    </inertial>
  </link>
  <joint name="right_joint_finger_2" type="revolute">
    <parent link="right_link_6"/>
    <child link="right_link_finger_2"/>
    <axis xyz="0 0 1"/>
    <origin rpy="-1.570796327 .649262481663582 -1.38614049188413" xyz="0.02226 -0.02707 -0.11482"/>
    <limit effort="2" lower="0" upper="1.51" velocity="1"/>
  </joint>
  <transmission name="right_joint_finger_2_trans">
    <type>transmission_interface/SimpleTransmission</type>
    <joint name="right_joint_finger_2">
      <hardwareInterface>hardware_interface/EffortJointInterface</hardwareInterface>
    </joint>
    <actuator name="right_joint_finger_2_actuator">
      <hardwareInterface>hardware_interface/EffortJointInterface</hardwareInterface>
      <mechanicalReduction>1</mechanicalReduction>
    </actuator>
  </transmission>
  <link name="right_link_finger_tip_2">
    <visual>
      <geometry>
        <mesh filename="package://kinova_description/meshes/finger_distal.dae"/>
      </geometry>
      <material name="carbon_fiber">
        <color rgba="0.792156862745098 0.819607843137255 0.933333333333333 1"/>
      </material>
    </visual>
    <collision>
      <geometry>
        <mesh filename="package://kinova_description/meshes/finger_distal.dae"/>
      </geometry>
    </collision>
    <inertial>
      <mass value="0.01"/>
      <origin xyz="0.022 0 0"/>
      <inertia ixx="7.8999684e-07" ixy="0" ixz="0" iyy="7.8999684e-07" iyz="0" izz="8e-08"/>
    </inertial>
  </link>
  <joint name="right_joint_finger_tip_2" type="revolute">
    <parent link="right_link_finger_2"/>
    <child link="right_link_finger_tip_2"/>
    <axis xyz="0 0 1"/>
    <origin rpy="0 0 0" xyz="0.044 -0.003 0"/>
    <limit effort="2" lower="0" upper="2" velocity="1"/>
  </joint>
  <transmission name="right_joint_finger_tip_2_trans">
    <type>transmission_interface/SimpleTransmission</type>
    <joint name="right_joint_finger_tip_2">
      <hardwareInterface>hardware_interface/EffortJointInterface</hardwareInterface>
    </joint>
    <actuator name="right_joint_finger_tip_2_actuator">
      <hardwareInterface>hardware_interface/EffortJointInterface</hardwareInterface>
      <mechanicalReduction>1</mechanicalReduction>
    </actuator>
  </transmission>
  <link name="right_link_finger_3">
    <visual>
      <geometry>
        <mesh filename="package://kinova_description/meshes/finger_proximal.dae"/>
      </geometry>
      <material name="carbon_fiber">
        <color rgba="0.792156862745098 0.819607843137255 0.933333333333333 1"/>
      </material>
    </visual>
    <collision>
      <geometry>
        <mesh filename="package://kinova_description/meshes/finger_proximal.dae"/>
      </geometry>
    </collision>
    <inertial>
      <mass value="0.01"/>
      <origin xyz="0.022 0 0"/>
      <inertia ixx="7.8999684e-07" ixy="0" ixz="0" iyy="7.8999684e-07" iyz="0" izz="8e-08"/>
    </inertial>
  </link>
  <joint name="right_joint_finger_3" type="revolute">
    <parent link="right_link_6"/>
    <child link="right_link_finger_3"/>
    <axis xyz="0 0 1"/>
    <origin rpy="-1.570796327 .649262481663582 -1.75545216211587" xyz="-0.02226 -0.02707 -0.11482"/>
    <limit effort="2" lower="0" upper="1.51" velocity="1"/>
  </joint>
  <transmission name="right_joint_finger_3_trans">
    <type>transmission_interface/SimpleTransmission</type>
    <joint name="right_joint_finger_3">
      <hardwareInterface>hardware_interface/EffortJointInterface</hardwareInterface>
    </joint>
    <actuator name="right_joint_finger_3_actuator">
      <hardwareInterface>hardware_interface/EffortJointInterface</hardwareInterface>
      <mechanicalReduction>1</mechanicalReduction>
    </actuator>
  </transmission>
  <link name="right_link_finger_tip_3">
    <visual>
      <geometry>
        <mesh filename="package://kinova_description/meshes/finger_distal.dae"/>
      </geometry>
      <material name="carbon_fiber">
        <color rgba="0.792156862745098 0.819607843137255 0.933333333333333 1"/>
      </material>
    </visual>
    <collision>
      <geometry>
        <mesh filename="package://kinova_description/meshes/finger_distal.dae"/>
      </geometry>
    </collision>
    <inertial>
      <mass value="0.01"/>
      <origin xyz="0.022 0 0"/>
      <inertia ixx="7.8999684e-07" ixy="0" ixz="0" iyy="7.8999684e-07" iyz="0" izz="8e-08"/>
    </inertial>
  </link>
  <joint name="right_joint_finger_tip_3" type="revolute">
    <parent link="right_link_finger_3"/>
    <child link="right_link_finger_tip_3"/>
    <axis xyz="0 0 1"/>
    <origin rpy="0 0 0" xyz="0.044 -0.003 0"/>
    <limit effort="2" lower="0" upper="2" velocity="1"/>
  </joint>
  <transmission name="right_joint_finger_tip_3_trans">
    <type>transmission_interface/SimpleTransmission</type>
    <joint name="right_joint_finger_tip_3">
      <hardwareInterface>hardware_interface/EffortJointInterface</hardwareInterface>
    </joint>
    <actuator name="right_joint_finger_tip_3_actuator">
      <hardwareInterface>hardware_interface/EffortJointInterface</hardwareInterface>
      <mechanicalReduction>1</mechanicalReduction>
    </actuator>
  </transmission>
  <!-- PTU 
    The flir_ptu_description package is either from system packages in
    /opt/ros/... or from source repository
    https://github.com/ros-drivers/flir_ptu
  -->
  <link name="ptu_tilt_link">
    <inertial>
      <mass value="0.65"/>
      <origin rpy="0 0 0" xyz="0 0 0"/>
      <inertia ixx="0.0001" ixy="0" ixz="0" iyy="0.0001" iyz="0" izz="0.0001"/>
    </inertial>
    <visual>
      <material name="ptu_body_color">
        <color rgba="0.3 0.3 0.3 1.0"/>
      </material>
      <geometry>
        <mesh filename="package://flir_ptu_description/meshes/flir-ptu-tilt-motor.stl"/>
      </geometry>
    </visual>
    <collision>
      <geometry>
        <mesh filename="package://flir_ptu_description/meshes/flir-ptu-tilt-motor-collision.stl"/>
      </geometry>
    </collision>
  </link>
  <gazebo reference="ptu_tilt_link">
    <material>Gazebo/DarkGrey</material>
  </gazebo>
  <link name="ptu_pan_link">
    <inertial>
      <mass value="0.65"/>
      <origin rpy="0 0 0" xyz="0 0 0"/>
      <inertia ixx="0.0001" ixy="0" ixz="0" iyy="0.0001" iyz="0" izz="0.0001"/>
    </inertial>
    <visual>
      <material name="ptu_body_color">
        <color rgba="0.3 0.3 0.3 1.0"/>
      </material>
      <geometry>
        <mesh filename="package://flir_ptu_description/meshes/flir-ptu-pan-motor.stl"/>
      </geometry>
    </visual>
    <collision>
      <geometry>
        <mesh filename="package://flir_ptu_description/meshes/flir-ptu-pan-motor-collision.stl"/>
      </geometry>
    </collision>
  </link>
  <gazebo reference="ptu_pan_link">
    <material>Gazebo/DarkGrey</material>
  </gazebo>
  <link name="ptu_base_link">
    <inertial>
      <mass value="2e-06"/>
      <inertia ixx="1.1e-09" ixy="0" ixz="0" iyy="1.1e-09" iyz="0" izz="1.1e-09"/>
    </inertial>
  </link>
  <link name="ptu_tilted_link">
    <visual>
      <material name="ptu_body_color">
        <color rgba="0.3 0.3 0.3 1.0"/>
      </material>
      <geometry>
        <mesh filename="package://flir_ptu_description/meshes/flir-ptu-camera-mount.stl"/>
      </geometry>
    </visual>
    <collision>
      <geometry>
        <mesh filename="package://flir_ptu_description/meshes/flir-ptu-camera-mount.stl"/>
      </geometry>
    </collision>
  </link>
  <link name="ptu_mount_link">
    <inertial>
      <mass value="2e-06"/>
      <inertia ixx="1.1e-09" ixy="0" ixz="0" iyy="1.1e-09" iyz="0" izz="1.1e-09"/>
    </inertial>
  </link>
  <joint name="ptu_base" type="fixed">
    <parent link="ptu_base_link"/>
    <child link="ptu_pan_link"/>
    <origin xyz="0 0 0"/>
  </joint>
  <!-- The pan joint -->
  <joint name="ptu_pan" type="revolute">
    <parent link="ptu_pan_link"/>
    <origin rpy="-1.5708 0 0.0" xyz="0 -0.00955 0.046774"/>
    <child link="ptu_tilt_link"/>
    <axis rpy="3.14159 0 0" xyz="0 -1 0"/>
    <limit effort="30" lower="-2.775" upper="2.775" velocity="1.0"/>
  </joint>
  <transmission name="ptu_pan_trans">
    <type>transmission_interface/SimpleTransmission</type>
    <joint name="ptu_pan">
      <hardwareInterface>PositionJointInterface</hardwareInterface>
    </joint>
    <actuator name="ptu_pan_motor">
      <mechanicalReduction>1</mechanicalReduction>
    </actuator>
  </transmission>
  <!-- The tilt joint -->
  <joint name="ptu_tilt" type="revolute">
    <parent link="ptu_tilt_link"/>
    <origin rpy="-1.5708 0 0" xyz="0 -0.043713 0"/>
    <child link="ptu_tilted_link"/>
    <axis xyz="0 1 0"/>
    <limit effort="30" lower="-0.82" upper="0.52" velocity="1.0"/>
  </joint>
  <transmission name="ptu_tilt_trans">
    <type>transmission_interface/SimpleTransmission</type>
    <joint name="ptu_tilt">
      <hardwareInterface>PositionJointInterface</hardwareInterface>
    </joint>
    <actuator name="ptu_tilt_motor">
      <mechanicalReduction>1</mechanicalReduction>
    </actuator>
  </transmission>
  <!-- Fixed joint to provide a convenient attachment point for accessories. -->
  <joint name="ptu_mount" type="fixed">
    <parent link="ptu_tilted_link"/>
    <child link="ptu_mount_link"/>
    <origin rpy="3.1416 0 0" xyz="0 0 -0.039116"/>
  </joint>
  <joint name="ptu_base_mount" type="fixed">
    <parent link="plinth"/>
    <child link="ptu_base_link"/>
    <origin xyz="0.152 0.03 0.91"/>
  </joint>
  <!-- kinect -->
  <link name="kinect">
    <visual name="kinect_visual">
      <geometry name="kinect_visual_geom">
        <box size="0.07 0.25 0.065"/>
        <origin xyz="0.03 0 0.035"/>
      </geometry>
      <material name="kinect_black_mat">
        <color rgba="0.0 0.0 0.0 1.0"/>
      </material>
    </visual>
    <collision name="kinect_collision">
      <geometry name="kinect_visual_geom">
        <box size="0.07 0.25 0.065"/>
        <origin xyz="0.03 0 0.035"/>
      </geometry>
    </collision>
  </link>
  <joint name="kinect_mount" type="fixed">
    <parent link="ptu_base_link"/>
    <child link="kinect"/>
    <origin xyz="0 0 0.0325"/>
  </joint>
  <!-- hack for depthimage_to_laserscan (todo: configure depthimage_to_laserscan to use "kinect" as frame -->
  <link name="camera_depth_frame">
    <origin xyz="0 0 0"/>
    <inertial>
      <mass value="0.0"/>
      <inertia ixx="1" ixy="0" ixz="0" iyy="1" iyz="0" izz="1"/>
    </inertial>
  </link>
  <joint name="camera_depth_frame_joint" type="fixed">
    <parent link="kinect"/>
    <child link="camera_depth_frame"/>
    <origin xyz="0 0 0"/>
  </joint>
</robot>

